b'Traceback (most recent call last):
  File "/home/nipun.batra/anaconda3/envs/gpflow/lib/python3.7/site-packages/pandas/core/indexes/base.py", line 2897, in get_loc
    return self._engine.get_loc(key)
  File "pandas/_libs/index.pyx", line 107, in pandas._libs.index.IndexEngine.get_loc
  File "pandas/_libs/index.pyx", line 131, in pandas._libs.index.IndexEngine.get_loc
  File "pandas/_libs/hashtable_class_helper.pxi", line 1607, in pandas._libs.hashtable.PyObjectHashTable.get_item
  File "pandas/_libs/hashtable_class_helper.pxi", line 1614, in pandas._libs.hashtable.PyObjectHashTable.get_item
KeyError: \'ts\'

During handling of the above exception, another exception occurred:

Traceback (most recent call last):
  File "called.py", line 373, in <module>
    args.datafile,
  File "called.py", line 65, in rmse_mae_over
    times = df[\'ts\'].unique()
  File "/home/nipun.batra/anaconda3/envs/gpflow/lib/python3.7/site-packages/pandas/core/frame.py", line 2980, in __getitem__
    indexer = self.columns.get_loc(key)
  File "/home/nipun.batra/anaconda3/envs/gpflow/lib/python3.7/site-packages/pandas/core/indexes/base.py", line 2899, in get_loc
    return self._engine.get_loc(self._maybe_cast_indexer(key))
  File "pandas/_libs/index.pyx", line 107, in pandas._libs.index.IndexEngine.get_loc
  File "pandas/_libs/index.pyx", line 131, in pandas._libs.index.IndexEngine.get_loc
  File "pandas/_libs/hashtable_class_helper.pxi", line 1607, in pandas._libs.hashtable.PyObjectHashTable.get_item
  File "pandas/_libs/hashtable_class_helper.pxi", line 1614, in pandas._libs.hashtable.PyObjectHashTable.get_item
KeyError: \'ts\'
'